### **Lecture Notes: Handling Errors in JavaScript Using `try`, `catch`, and `finally`**

In JavaScript, error handling is important to prevent the program from crashing and to manage exceptional situations that occur during runtime. JavaScript provides a powerful mechanism to handle errors through the `try`, `catch`, and `finally` blocks.

---

#### **1. Introduction to `try`, `catch`, and `finally`**

- **`try` block**: Contains code that might throw an error.
- **`catch` block**: Catches any errors thrown in the `try` block and handles them. It allows us to access the error object to get the details of the error.
- **`finally` block**: This block is optional and will always execute regardless of whether an error occurs or not. It is typically used for cleanup code, such as closing files or releasing resources.

---

#### **2. Basic Usage of `try` and `catch`**

A simple `try-catch` example is used to catch runtime errors like undefined variables.

```javascript
try {
    console.log(x) // x is not defined
} catch (error) {
    console.log(error.message) // Logs the error message
}
```
- In this case, the variable `x` is not defined, which throws a `ReferenceError`, and the error is caught and logged.

---

#### **3. Handling Errors with Invalid Inputs or Operations**

```javascript
try {
    let arr = new Array(-5) // Invalid array size
    console.log(arr)
} catch (error) {
    console.log(error.message) // Logs the error message
}
```
- Here, trying to create an array with a negative size is invalid and throws a `RangeError`. This can be caught and logged using `catch`.

---

#### **4. Manually Throwing Errors**

You can also throw custom errors using `throw` inside a `try` block.

```javascript
try {
    let num = 12;
    if (num < 0) {
        throw new Error("Num should be greater than zero") // Custom error
    }
} catch (error) {
    console.log(error.message) // Logs the custom error message
}
```
- In this example, we check a condition (if `num < 0`) and manually throw an error if the condition is met.

---

#### **5. Catching Specific Error Types**

JavaScript allows us to catch and handle specific types of errors (like `SyntaxError`).

```javascript
try {
    console.log(x); // Undefined variable
    throw new SyntaxError("This is a custom syntax error"); // Custom error
} catch (error) {
    if (error instanceof SyntaxError) {
        console.log("Caught a syntax error:", error.message) // Handle SyntaxError
    } else {
        console.log("Caught some other error:", error.message) // Handle other errors
    }
}
```
- This example shows how we can specifically check for `SyntaxError` using `instanceof` and handle it differently from other types of errors.

---

#### **6. Example with `TypeError` (Undefined Object Property)**

```javascript
try {
    let obj;
    console.log(obj.message); // This will throw a TypeError
} catch (error) {
    console.log(error.name); // TypeError name
    console.log(error.message); // Detailed error message
    console.log(error.stack); // Stack trace
}
```
- If you try to access a property (`message`) of an `undefined` variable (`obj`), a `TypeError` occurs. The `catch` block provides detailed information, such as the name, message, and stack trace of the error.

---

#### **7. Using `finally` for Cleanup**

The `finally` block always runs, regardless of whether an error is thrown or not.

```javascript
try {
    let x;
    console.log(x) // Undefined variable
} catch (error) {
    console.log(error.message) // Logs the error message
} finally {
    console.log("Cleanup..") // Always executed
}
```
- This example shows how to use the `finally` block to perform cleanup actions (like closing a file, releasing resources) after the `try-catch` block is executed.

---

#### **8. Demonstrating the `finally` Block with a Function**

```javascript
function testFinally() {
  try {
    console.log("Inside try block"); // Normal execution
    // Uncomment the next line to see the catch block in action
    // throw new Error("An error occurred");
  } catch (error) {
    console.log("Inside catch block: " + error.message); // Error handling
  } finally {
    console.log("This is always executed, in the finally block."); // Always executed
  }
}

testFinally(); // Calling the function to see the result
```
- In this function, even if an error is thrown in the `try` block (which is optional), the `finally` block will always execute, making it ideal for final steps that need to run no matter what.

---

#### **9. Note:**

- **`try`**: Defines a block of code to test for errors.
- **`catch`**: Defines a block of code to handle errors if any are thrown in the `try` block.
- **`finally`**: Executes code after `try-catch`, regardless of whether an error occurred, useful for cleanup tasks.
- You can use `throw` to manually trigger errors, and use `instanceof` to handle specific types of errors like `SyntaxError`, `ReferenceError`, etc.

---

